Workbook
Name Lista_Calificacion: 'Otras listas'!$W$6:$W$10
Name Lista_Combustible: 'Otras listas'!$L$6:$L$10
Name Lista_Conductores: Conductores[Conductor]
Name Lista_Estaciones: 'Otras listas'!$J$6:$J$13
Name Lista_infraccion: 'Otras listas'!$U$6:$U$11
Name Lista_Marcas: Marcas[Marcas]
Name Lista_Modelos: OFFSET(Modelos[[#Headers],[Modelo]],MATCH('Flota Vehicular'!$F1,Modelos[Marcas],0),0,COUNTIF(Modelos[Marcas],'Flota Vehicular'!$F1))
Name Lista_PaqMnnto: 'Otras listas'!$P$6:$P$28
Name Lista_Placas: 'Flota Vehicular'!$H$6:$H$34
Name Lista_Poliza: Seguros!$F$4:$F$23
Name Lista_Servicios: 'Otras listas'!$S$6:$S$28
Name Lista_Talleres: Talleres!$D$4:$D$23
Name Lista_Tipo_Vehiculo: Tipo_Vehiculo[Tipo Vehiculo]
Name Lista_TipoMnnto: 'Otras listas'!$N$6:$N$8

Sheet Flota Vehicular
B1: FLOTA DE VEHICULOS PROYECTO ENAP
C3: DATOS PRINCIPALES Y DISPONIBILIDAD DEL VEHÍCULO | N3: DATOS Y CONTROL DEL MANTENIMIENTO PREVENTIVO
C5: Nro | D5: PLACA | E5: TIPO | F5: MARCA | G5: MODELO | H5: Placa Vehiculo | I5: NRO DE SERIE | J5: COLOR | K5: AÑO | L5: Toneladas (Tn) | M5: Estado Vehiculo | N5: Ciclo para Mnnto Prevent. Motor (Kms) | O5: Ciclo para Mnnto Preventivo Caja y Diferencial | P5: Kms Odómetro Inicial | Q5: Kms Último Mnnto. Preventivo Motor | R5: Kms Último Mnnto Preve Caja y Diferencial | S5: Kms Odómetro Actual | T5: Kms Faltantes Mannto Prev. Cajas y Diferencial | U5: Kms faltantes Mnnto Prev. Motor (Km) | V5: Estado Mantenimiento Preventivo
C6: =ROW(A1) -> 1 | D6: QAA-3164 | E6: ARTICULADO | F6: SHACMAN | G6: CABEZAL | H6: QAA-3164 | I6: 71126425 | J6: BLANCO | K6: 2025 | L6: 25 | M6: =IF(H6="","",IF(_xlfn.MAXIFS(Mantenimiento[Fecha Salida],Mantenimiento[Placa Vehiculo],H6)>TODAY(),"Mantenimiento",IF(IFERROR(INDEX(Seguros[Estado Poliza],MATCH(H6,Seguros[Placa Vehiculo],0)),"")="Vencido","Seguro Vencido","Disponible"))) -> Disponible | N6: 8000 | O6: 60000 | P6: 200 | Q6: =_xlfn.MAXIFS(Mantenimiento[Kilometraje del Odómetro],Mantenimiento[Placa Vehiculo],H6,Mantenimiento[Tipo],"Preventivo") -> 38310 | R6: =_xlfn.MAXIFS(Mantenimiento[Kilometraje del Odómetro],Mantenimiento[Placa Vehiculo],H6,Mantenimiento[Tipo],"Prev Caja y Corona") -> 0 | S6: =_xlfn.MAXIFS(Rutas[Kms Final (Odómetro)],Rutas[Placa Vehiculo],H6) -> 44777 | T6: =IF(H6="","",O6-(IF(S6=0,P6,S6)-R6)) -> 15223 | U6: =IF(H6="","",N6-(IF(S6=0,P6,S6)-Q6)) -> 1533 | V6: =IFERROR(IF(OR(M6="Mantenimiento",U6/N6<=5%),"Mantener",IF(U6/N6<=20%,"Falta poco","Aun no")),"") -> Falta poco
C7: =ROW(A2) -> 2 | D7: QAA-3166 | E7: ARTICULADO | F7: SHACMAN | G7: CABEZAL | H7: QAA-3166 | I7: 71122862 | J7: BLANCO | K7: 2024 | L7: 25 | M7: =IF(H7="","",IF(_xlfn.MAXIFS(Mantenimiento[Fecha Salida],Mantenimiento[Placa Vehiculo],H7)>TODAY(),"Mantenimiento",IF(IFERROR(INDEX(Seguros[Estado Poliza],MATCH(H7,Seguros[Placa Vehiculo],0)),"")="Vencido","Seguro Vencido","Disponible"))) -> Disponible | N7: 8000 | O7: 60000 | P7: 200 | Q7: =_xlfn.MAXIFS(Mantenimiento[Kilometraje del Odómetro],Mantenimiento[Placa Vehiculo],H7,Mantenimiento[Tipo],"Preventivo") -> 52969 | R7: =_xlfn.MAXIFS(Mantenimiento[Kilometraje del Odómetro],Mantenimiento[Placa Vehiculo],H7,Mantenimiento[Tipo],"Prev Caja y Corona") -> 0 | S7: =_xlfn.MAXIFS(Rutas[Kms Final (Odómetro)],Rutas[Placa Vehiculo],H7) -> 59247 | T7: =IF(H7="","",O7-(IF(S7=0,P7,S7)-R7)) -> 753 | U7: =IF(H7="","",N7-(IF(S7=0,P7,S7)-Q7)) -> 1722 | V7: =IFERROR(IF(OR(M7="Mantenimiento",U7/N7<=5%),"Mantener",IF(U7/N7<=20%,"Falta poco","Aun no")),"") -> Aun no
C8: 3 | D8: QAA-2912 | E8: ARTICULADO | F8: DAF | G8: CABEZAL | H8: QAA-2912 | I8: A517778 | J8: AMARILLO | K8: 2023 | L8: 40 | M8: =IF(H8="","",IF(_xlfn.MAXIFS(Mantenimiento[Fecha Salida],Mantenimiento[Placa Vehiculo],H8)>TODAY(),"Mantenimiento",IF(IFERROR(INDEX(Seguros[Estado Poliza],MATCH(H8,Seguros[Placa Vehiculo],0)),"")="Vencido","Seguro Vencido","Disponible"))) -> Disponible | N8: 8000 | O8: 60000 | P8: 200 | Q8: =_xlfn.MAXIFS(Mantenimiento[Kilometraje del Odómetro],Mantenimiento[Placa Vehiculo],H8,Mantenimiento[Tipo],"Preventivo") -> 124870 | R8: =_xlfn.MAXIFS(Mantenimiento[Kilometraje del Odómetro],Mantenimiento[Placa Vehiculo],H8,Mantenimiento[Tipo],"Prev Caja y Corona") -> 82764 | S8: =_xlfn.MAXIFS(Rutas[Kms Final (Odómetro)],Rutas[Placa Vehiculo],H8) -> 131338 | T8: =IF(H8="","",O8-(IF(S8=0,P8,S8)-R8)) -> 11426 | U8: =IF(H8="","",N8-(IF(S8=0,P8,S8)-Q8)) -> 1532 | V8: =IFERROR(IF(OR(M8="Mantenimiento",U8/N8<=5%),"Mantener",IF(U8/N8<=20%,"Falta poco","Aun no")),"") -> Falta poco
C9: 4 | D9: QAA-2915 | E9: ARTICULADO | F9: DAF | G9: CABEZAL | H9: QAA-2915 | I9: A516026 | J9: BLANCO | K9: 2023 | L9: 40 | M9: =IF(H9="","",IF(_xlfn.MAXIFS(Mantenimiento[Fecha Salida],Mantenimiento[Placa Vehiculo],H9)>TODAY(),"Mantenimiento",IF(IFERROR(INDEX(Seguros[Estado Poliza],MATCH(H9,Seguros[Placa Vehiculo],0)),"")="Vencido","Seguro Vencido","Disponible"))) -> Disponible | N9: 8000 | O9: 60000 | P9: 200 | Q9: =_xlfn.MAXIFS(Mantenimiento[Kilometraje del Odómetro],Mantenimiento[Placa Vehiculo],H9,Mantenimiento[Tipo],"Preventivo") -> 127486 | R9: =_xlfn.MAXIFS(Mantenimiento[Kilometraje del Odómetro],Mantenimiento[Placa Vehiculo],H9,Mantenimiento[Tipo],"Prev Caja y Corona") -> 82494 | S9: =_xlfn.MAXIFS(Rutas[Kms Final (Odómetro)],Rutas[Placa Vehiculo],H9) -> 130806 | T9: =IF(H9="","",O9-(IF(S9=0,P9,S9)-R9)) -> 11688 | U9: =IF(H9="","",N9-(IF(S9=0,P9,S9)-Q9)) -> 4680 | V9: =IFERROR(IF(OR(M9="Mantenimiento",U9/N9<=5%),"Mantener",IF(U9/N9<=20%,"Falta poco","Aun no")),"") -> Aun no
C10: 5 | D10: QAA-2916 | E10: ARTICULADO | F10: DAF | G10: CABEZAL | H10: QAA-2916 | I10: A517802 | J10: AMARILLO | K10: 2023 | L10: 40 | M10: =IF(H10="","",IF(_xlfn.MAXIFS(Mantenimiento[Fecha Salida],Mantenimiento[Placa Vehiculo],H10)>TODAY(),"Mantenimiento",IF(IFERROR(INDEX(Seguros[Estado Poliza],MATCH(H10,Seguros[Placa Vehiculo],0)),"")="Vencido","Seguro Vencido","Disponible"))) -> Disponible | N10: 8000 | O10: 60000 | P10: 200 | Q10: =_xlfn.MAXIFS(Mantenimiento[Kilometraje del Odómetro],Mantenimiento[Placa Vehiculo],H10,Mantenimiento[Tipo],"Preventivo") -> 112441 | R10: =_xlfn.MAXIFS(Mantenimiento[Kilometraje del Odómetro],Mantenimiento[Placa Vehiculo],H10,Mantenimiento[Tipo],"Prev Caja y Corona") -> 91080 | S10: =_xlfn.MAXIFS(Rutas[Kms Final (Odómetro)],Rutas[Placa Vehiculo],H10) -> 118200 | T10: =IF(H10="","",O10-(IF(S10=0,P10,S10)-R10)) -> 32880 | U10: =IF(H10="","",N10-(IF(S10=0,P10,S10)-Q10)) -> 2241 | V10: =IFERROR(IF(OR(M10="Mantenimiento",U10/N10<=5%),"Mantener",IF(U10/N10<=20%,"Falta poco","Aun no")),"") -> Aun no
C11: 6 | D11: PAB-3424 | E11: CAMIÓN RIGIDO | F11: HINO | G11: RIGIDO | H11: PAB-3424 | I11: P11CVT20663 | J11: BLANCO | K11: 2021 | L11: 6 | M11: =IF(H11="","",IF(_xlfn.MAXIFS(Mantenimiento[Fecha Salida],Mantenimiento[Placa Vehiculo],H11)>TODAY(),"Mantenimiento",IF(IFERROR(INDEX(Seguros[Estado Poliza],MATCH(H11,Seguros[Placa Vehiculo],0)),"")="Vencido","Seguro Vencido","Disponible"))) -> Disponible | N11: 8000 | O11: 60000 | P11: 150000 | Q11: =_xlfn.MAXIFS(Mantenimiento[Kilometraje del Odómetro],Mantenimiento[Placa Vehiculo],H11,Mantenimiento[Tipo],"Preventivo") -> 365806 | R11: =_xlfn.MAXIFS(Mantenimiento[Kilometraje del Odómetro],Mantenimiento[Placa Vehiculo],H11,Mantenimiento[Tipo],"Prev Caja y Corona") -> 358316 | S11: =_xlfn.MAXIFS(Rutas[Kms Final (Odómetro)],Rutas[Placa Vehiculo],H11) -> 370695 | T11: =IF(H11="","",O11-(IF(S11=0,P11,S11)-R11)) -> 47621 | U11: =IF(H11="","",N11-(IF(S11=0,P11,S11)-Q11)) -> 3111 | V11: =IFERROR(IF(OR(M11="Mantenimiento",U11/N11<=5%),"Mantener",IF(U11/N11<=20%,"Falta poco","Aun no")),"") -> Aun no
C12: 7 | D12: QAA-3165 | E12: ARTICULADO | F12: SHACMAN | G12: CABEZAL | H12: QAA-3165 | I12: 71126426 | J12: BLANCO | K12: 2024 | L12: 25 | M12: =IF(H12="","",IF(_xlfn.MAXIFS(Mantenimiento[Fecha Salida],Mantenimiento[Placa Vehiculo],H12)>TODAY(),"Mantenimiento",IF(IFERROR(INDEX(Seguros[Estado Poliza],MATCH(H12,Seguros[Placa Vehiculo],0)),"")="Vencido","Seguro Vencido","Disponible"))) -> Disponible | N12: 8000 | O12: 60000 | P12: 200 | Q12: =_xlfn.MAXIFS(Mantenimiento[Kilometraje del Odómetro],Mantenimiento[Placa Vehiculo],H12,Mantenimiento[Tipo],"Preventivo") -> 63543 | R12: =_xlfn.MAXIFS(Mantenimiento[Kilometraje del Odómetro],Mantenimiento[Placa Vehiculo],H12,Mantenimiento[Tipo],"Prev Caja y Corona") -> 63543 | S12: =_xlfn.MAXIFS(Rutas[Kms Final (Odómetro)],Rutas[Placa Vehiculo],H12) -> 65856 | T12: =IF(H12="","",O12-(IF(S12=0,P12,S12)-R12)) -> 57687 | U12: =IF(H12="","",N12-(IF(S12=0,P12,S12)-Q12)) -> 5687 | V12: =IFERROR(IF(OR(M12="Mantenimiento",U12/N12<=5%),"Mantener",IF(U12/N12<=20%,"Falta poco","Aun no")),"") -> Aun no
C13: 8 | D13: QAA-1976 | E13: ARTICULADO | F13: HINO | G13: CABEZAL | H13: QAA-1976 | I13: E13CWT20044 | J13: BLANCO | K13: 2023 | L13: 27 | M13: =IF(H13="","",IF(_xlfn.MAXIFS(Mantenimiento[Fecha Salida],Mantenimiento[Placa Vehiculo],H13)>TODAY(),"Mantenimiento",IF(IFERROR(INDEX(Seguros[Estado Poliza],MATCH(H13,Seguros[Placa Vehiculo],0)),"")="Vencido","Seguro Vencido","Disponible"))) -> Disponible | N13: 6000 | O13: 60000 | P13: 150000 | Q13: =_xlfn.MAXIFS(Mantenimiento[Kilometraje del Odómetro],Mantenimiento[Placa Vehiculo],H13,Mantenimiento[Tipo],"Preventivo") -> 275504 | R13: =_xlfn.MAXIFS(Mantenimiento[Kilometraje del Odómetro],Mantenimiento[Placa Vehiculo],H13,Mantenimiento[Tipo],"Prev Caja y Corona") -> 268934 | S13: =_xlfn.MAXIFS(Rutas[Kms Final (Odómetro)],Rutas[Placa Vehiculo],H13) -> 274819 | T13: =IF(H13="","",O13-(IF(S13=0,P13,S13)-R13)) -> 54115 | U13: =IF(H13="","",N13-(IF(S13=0,P13,S13)-Q13)) -> 6685 | V13: =IFERROR(IF(OR(M13="Mantenimiento",U13/N13<=5%),"Mantener",IF(U13/N13<=20%,"Falta poco","Aun no")),"") -> Aun no
C14: 9 | D14: IAA-2747 | E14: CAMIÓN RIGIDO | F14: HINO | G14: RIGIDO | H14: IAA-2747 | I14: J08EWG10689 | J14: BLANCO | K14: 2022 | L14: 18.87 | M14: =IF(H14="","",IF(_xlfn.MAXIFS(Mantenimiento[Fecha Salida],Mantenimiento[Placa Vehiculo],H14)>TODAY(),"Mantenimiento",IF(IFERROR(INDEX(Seguros[Estado Poliza],MATCH(H14,Seguros[Placa Vehiculo],0)),"")="Vencido","Seguro Vencido","Disponible"))) -> Disponible | N14: 5000 | O14: 60000 | P14: 160000 | Q14: =_xlfn.MAXIFS(Mantenimiento[Kilometraje del Odómetro],Mantenimiento[Placa Vehiculo],H14,Mantenimiento[Tipo],"Preventivo") -> 430325 | R14: =_xlfn.MAXIFS(Mantenimiento[Kilometraje del Odómetro],Mantenimiento[Placa Vehiculo],H14,Mantenimiento[Tipo],"Prev Caja y Corona") -> 402043 | S14: =_xlfn.MAXIFS(Rutas[Kms Final (Odómetro)],Rutas[Placa Vehiculo],H14) -> 431668 | T14: =IF(H14="","",O14-(IF(S14=0,P14,S14)-R14)) -> 30375 | U14: =IF(H14="","",N14-(IF(S14=0,P14,S14)-Q14)) -> 3657 | V14: =IFERROR(IF(OR(M14="Mantenimiento",U14/N14<=5%),"Mantener",IF(U14/N14<=20%,"Falta poco","Aun no")),"") -> Aun no
C15: 10 | D15: QAA-3180 | E15: ARTICULADO | F15: SHACMAN | G15: CABEZAL | H15: QAA-3180 | I15: 71130145 | J15: PLOMO | K15: 2025 | L15: 25 | M15: =IF(H15="","",IF(_xlfn.MAXIFS(Mantenimiento[Fecha Salida],Mantenimiento[Placa Vehiculo],H15)>TODAY(),"Mantenimiento",IF(IFERROR(INDEX(Seguros[Estado Poliza],MATCH(H15,Seguros[Placa Vehiculo],0)),"")="Vencido","Seguro Vencido","Disponible"))) -> Disponible | N15: 6000 | O15: 60000 | P15: 300 | Q15: =_xlfn.MAXIFS(Mantenimiento[Kilometraje del Odómetro],Mantenimiento[Placa Vehiculo],H15,Mantenimiento[Tipo],"Preventivo") -> 18278 | R15: =_xlfn.MAXIFS(Mantenimiento[Kilometraje del Odómetro],Mantenimiento[Placa Vehiculo],H15,Mantenimiento[Tipo],"Prev Caja y Corona") -> 0 | S15: =_xlfn.MAXIFS(Rutas[Kms Final (Odómetro)],Rutas[Placa Vehiculo],H15) -> 14931 | T15: =IF(H15="","",O15-(IF(S15=0,P15,S15)-R15)) -> 45069 | U15: =IF(H15="","",N15-(IF(S15=0,P15,S15)-Q15)) -> 9347 | V15: =IFERROR(IF(OR(M15="Mantenimiento",U15/N15<=5%),"Mantener",IF(U15/N15<=20%,"Falta poco","Aun no")),"") -> Aun no
C16: 11 | D16: PFF-2857 | E16: CAMIONETA | F16: CHEVROLET | G16: DMAX | H16: PFF-2857 | I16: 4JK1ZH1718 | J16: BLANCO | K16: 2024 | L16: 1 | M16: =IF(H16="","",IF(_xlfn.MAXIFS(Mantenimiento[Fecha Salida],Mantenimiento[Placa Vehiculo],H16)>TODAY(),"Mantenimiento",IF(IFERROR(INDEX(Seguros[Estado Poliza],MATCH(H16,Seguros[Placa Vehiculo],0)),"")="Vencido","Seguro Vencido","Disponible"))) -> Disponible | N16: 6000 | O16: 40000 | P16: 300 | Q16: =_xlfn.MAXIFS(Mantenimiento[Kilometraje del Odómetro],Mantenimiento[Placa Vehiculo],H16,Mantenimiento[Tipo],"Preventivo") -> 111097 | R16: =_xlfn.MAXIFS(Mantenimiento[Kilometraje del Odómetro],Mantenimiento[Placa Vehiculo],H16,Mantenimiento[Tipo],"Prev Caja y Corona") -> 85960 | S16: =_xlfn.MAXIFS(Rutas[Kms Final (Odómetro)],Rutas[Placa Vehiculo],H16) -> 115045 | T16: =IF(H16="","",O16-(IF(S16=0,P16,S16)-R16)) -> 10915 | U16: =IF(H16="","",N16-(IF(S16=0,P16,S16)-Q16)) -> 2052 | V16: =IFERROR(IF(OR(M16="Mantenimiento",U16/N16<=5%),"Mantener",IF(U16/N16<=20%,"Falta poco","Aun no")),"") -> Aun no
C17: =ROW(A12) -> 12 | D17: QAA-3074 | E17: ARTICULADO | F17: DAF | G17: CABEZAL | H17: QAA-3074 | I17: A548013 | J17: AMARILLO | K17: 2024 | L17: 26 | M17: =IF(H17="","",IF(_xlfn.MAXIFS(Mantenimiento[Fecha Salida],Mantenimiento[Placa Vehiculo],H17)>TODAY(),"Mantenimiento",IF(IFERROR(INDEX(Seguros[Estado Poliza],MATCH(H17,Seguros[Placa Vehiculo],0)),"")="Vencido","Seguro Vencido","Disponible"))) -> Disponible | N17: 8000 | O17: 60000 | P17: 200 | Q17: =_xlfn.MAXIFS(Mantenimiento[Kilometraje del Odómetro],Mantenimiento[Placa Vehiculo],H17,Mantenimiento[Tipo],"Preventivo") -> 28686 | R17: =_xlfn.MAXIFS(Mantenimiento[Kilometraje del Odómetro],Mantenimiento[Placa Vehiculo],H17,Mantenimiento[Tipo],"Prev Caja y Corona") -> 0 | S17: =_xlfn.MAXIFS(Rutas[Kms Final (Odómetro)],Rutas[Placa Vehiculo],H17) -> 33139 | T17: =IF(H17="","",O17-(IF(S17=0,P17,S17)-R17)) -> 26861 | U17: =IF(H17="","",N17-(IF(S17=0,P17,S17)-Q17)) -> 3547 | V17: =IFERROR(IF(OR(M17="Mantenimiento",U17/N17<=5%),"Mantener",IF(U17/N17<=20%,"Falta poco","Aun no")),"") -> Aun no
C18: 13 | D18: QAA-3220 | E18: ARTICULADO | F18: DAF | G18: CABEZAL | H18: QAA-3220 | I18: A547787 | J18: AMARILLO | K18: 2024 | L18: 26 | M18: =IF(H18="","",IF(_xlfn.MAXIFS(Mantenimiento[Fecha Salida],Mantenimiento[Placa Vehiculo],H18)>TODAY(),"Mantenimiento",IF(IFERROR(INDEX(Seguros[Estado Poliza],MATCH(H18,Seguros[Placa Vehiculo],0)),"")="Vencido","Seguro Vencido","Disponible"))) -> Disponible | N18: 8000 | O18: 60000 | P18: 3000 | Q18: =_xlfn.MAXIFS(Mantenimiento[Kilometraje del Odómetro],Mantenimiento[Placa Vehiculo],H18,Mantenimiento[Tipo],"Preventivo") -> 54068 | R18: =_xlfn.MAXIFS(Mantenimiento[Kilometraje del Odómetro],Mantenimiento[Placa Vehiculo],H18,Mantenimiento[Tipo],"Prev Caja y Corona") -> 0 | S18: =_xlfn.MAXIFS(Rutas[Kms Final (Odómetro)],Rutas[Placa Vehiculo],H18) -> 57649 | T18: =IF(H18="","",O18-(IF(S18=0,P18,S18)-R18)) -> 2351 | U18: =IF(H18="","",N18-(IF(S18=0,P18,S18)-Q18)) -> 4419 | V18: =IFERROR(IF(OR(M18="Mantenimiento",U18/N18<=5%),"Mantener",IF(U18/N18<=20%,"Falta poco","Aun no")),"") -> Aun no
C19: 14 | D19: QAA-3108 | E19: ARTICULADO | F19: DAF | G19: CABEZAL | H19: QAA-3108 | I19: A625086 | J19: AMARILLO | K19: 2026 | L19: 26 | M19: =IF(H19="","",IF(_xlfn.MAXIFS(Mantenimiento[Fecha Salida],Mantenimiento[Placa Vehiculo],H19)>TODAY(),"Mantenimiento",IF(IFERROR(INDEX(Seguros[Estado Poliza],MATCH(H19,Seguros[Placa Vehiculo],0)),"")="Vencido","Seguro Vencido","Disponible"))) -> Disponible | N19: 8000 | O19: 60000 | P19: 300 | Q19: =_xlfn.MAXIFS(Mantenimiento[Kilometraje del Odómetro],Mantenimiento[Placa Vehiculo],H19,Mantenimiento[Tipo],"Preventivo") -> 0 | R19: =_xlfn.MAXIFS(Mantenimiento[Kilometraje del Odómetro],Mantenimiento[Placa Vehiculo],H19,Mantenimiento[Tipo],"Prev Caja y Corona") -> 0 | S19: =_xlfn.MAXIFS(Rutas[Kms Final (Odómetro)],Rutas[Placa Vehiculo],H19) -> 6798 | T19: =IF(H19="","",O19-(IF(S19=0,P19,S19)-R19)) -> 53202 | U19: =IF(H19="","",N19-(IF(S19=0,P19,S19)-Q19)) -> 1202 | V19: =IFERROR(IF(OR(M19="Mantenimiento",U19/N19<=5%),"Mantener",IF(U19/N19<=20%,"Falta poco","Aun no")),"") -> Falta poco
C20: 15 | D20: QAA-1974 | E20: ARTICULADO | F20: HINO | G20: CABEZAL | H20: QAA-1974 | I20: E13CWT20046 | J20: BLANCO | K20: 2018 | L20: 17 | M20: =IF(H20="","",IF(_xlfn.MAXIFS(Mantenimiento[Fecha Salida],Mantenimiento[Placa Vehiculo],H20)>TODAY(),"Mantenimiento",IF(IFERROR(INDEX(Seguros[Estado Poliza],MATCH(H20,Seguros[Placa Vehiculo],0)),"")="Vencido","Seguro Vencido","Disponible"))) -> Disponible | N20: 6000 | O20: 80000 | P20: 1500 | Q20: =_xlfn.MAXIFS(Mantenimiento[Kilometraje del Odómetro],Mantenimiento[Placa Vehiculo],H20,Mantenimiento[Tipo],"Preventivo") -> 228659 | R20: =_xlfn.MAXIFS(Mantenimiento[Kilometraje del Odómetro],Mantenimiento[Placa Vehiculo],H20,Mantenimiento[Tipo],"Prev Caja y Corona") -> 203550 | S20: =_xlfn.MAXIFS(Rutas[Kms Final (Odómetro)],Rutas[Placa Vehiculo],H20) -> 230044 | T20: =IF(H20="","",O20-(IF(S20=0,P20,S20)-R20)) -> 53506 | U20: =IF(H20="","",N20-(IF(S20=0,P20,S20)-Q20)) -> 4615 | V20: =IFERROR(IF(OR(M20="Mantenimiento",U20/N20<=5%),"Mantener",IF(U20/N20<=20%,"Falta poco","Aun no")),"") -> Aun no
C21: 16 | D21: PFG-2722 | E21: ARTICULADO | F21: QINGLING | G21: CABEZAL | H21: PFG-2722 | I21: G533087 | J21: BLANCO | K21: 2024 | L21: 20 | M21: =IF(H21="","",IF(_xlfn.MAXIFS(Mantenimiento[Fecha Salida],Mantenimiento[Placa Vehiculo],H21)>TODAY(),"Mantenimiento",IF(IFERROR(INDEX(Seguros[Estado Poliza],MATCH(H21,Seguros[Placa Vehiculo],0)),"")="Vencido","Seguro Vencido","Disponible"))) -> Disponible | N21: 10000 | O21: 60000 | P21: 150000 | Q21: =_xlfn.MAXIFS(Mantenimiento[Kilometraje del Odómetro],Mantenimiento[Placa Vehiculo],H21,Mantenimiento[Tipo],"Preventivo") -> 210065 | R21: =_xlfn.MAXIFS(Mantenimiento[Kilometraje del Odómetro],Mantenimiento[Placa Vehiculo],H21,Mantenimiento[Tipo],"Prev Caja y Corona") -> 191408 | S21: =_xlfn.MAXIFS(Rutas[Kms Final (Odómetro)],Rutas[Placa Vehiculo],H21) -> 214526 | T21: =IF(H21="","",O21-(IF(S21=0,P21,S21)-R21)) -> 36882 | U21: =IF(H21="","",N21-(IF(S21=0,P21,S21)-Q21)) -> 5539 | V21: =IFERROR(IF(OR(M21="Mantenimiento",U21/N21<=5%),"Mantener",IF(U21/N21<=20%,"Falta poco","Aun no")),"") -> Aun no
C22: 17 | D22: KR-1189/42416 | E22: VACUMM | F22: VACUUM | G22: 160 BARRILES | H22: KR-1189/42416 | I22: 8R8RFNS26B9J01843 | J22: BLANCO-ROJO | K22: 2011 | L22: 5 | M22: =IF(H22="","",IF(_xlfn.MAXIFS(Mantenimiento[Fecha Salida],Mantenimiento[Placa Vehiculo],H22)>TODAY(),"Mantenimiento",IF(IFERROR(INDEX(Seguros[Estado Poliza],MATCH(H22,Seguros[Placa Vehiculo],0)),"")="Vencido","Seguro Vencido","Disponible"))) -> Disponible | N22: 250 | P22: 2 | Q22: =_xlfn.MAXIFS(Mantenimiento[Kilometraje del Odómetro],Mantenimiento[Placa Vehiculo],H22,Mantenimiento[Tipo],"Preventivo") -> 2165 | R22: =_xlfn.MAXIFS(Mantenimiento[Kilometraje del Odómetro],Mantenimiento[Placa Vehiculo],H22,Mantenimiento[Tipo],"Prev Caja y Corona") -> 0 | S22: =_xlfn.MAXIFS(Rutas[Kms Final (Odómetro)],Rutas[Placa Vehiculo],H22) -> 2316 | U22: =IF(H22="","",N22-(IF(S22=0,P22,S22)-Q22)) -> 99 | V22: =IFERROR(IF(OR(M22="Mantenimiento",U22/N22<=5%),"Mantener",IF(U22/N22<=20%,"Falta poco","Aun no")),"") -> Aun no
C23: 18 | D23: KR-1172/42409 | E23: VACUMM | F23: VACUUM | G23: 160 BARRILES | H23: KR-1172/42409 | I23: 8R8RFNS2899J01854 | J23: BLANCO-ROJO | K23: 2009 | L23: 5 | M23: =IF(H23="","",IF(_xlfn.MAXIFS(Mantenimiento[Fecha Salida],Mantenimiento[Placa Vehiculo],H23)>TODAY(),"Mantenimiento",IF(IFERROR(INDEX(Seguros[Estado Poliza],MATCH(H23,Seguros[Placa Vehiculo],0)),"")="Vencido","Seguro Vencido","Disponible"))) -> Disponible | N23: 250 | P23: 1000 | Q23: =_xlfn.MAXIFS(Mantenimiento[Kilometraje del Odómetro],Mantenimiento[Placa Vehiculo],H23,Mantenimiento[Tipo],"Preventivo") -> 4896 | R23: =_xlfn.MAXIFS(Mantenimiento[Kilometraje del Odómetro],Mantenimiento[Placa Vehiculo],H23,Mantenimiento[Tipo],"Prev Caja y Corona") -> 0 | S23: =_xlfn.MAXIFS(Rutas[Kms Final (Odómetro)],Rutas[Placa Vehiculo],H23) -> 4986 | U23: =IF(H23="","",N23-(IF(S23=0,P23,S23)-Q23)) -> 160 | V23: =IFERROR(IF(OR(M23="Mantenimiento",U23/N23<=5%),"Mantener",IF(U23/N23<=20%,"Falta poco","Aun no")),"") -> Aun no
C24: 19 | D24: KR-1344/42429 | E24: VACUMM | F24: VACUUM | G24: 200 BARRILES | H24: KR-1344/42429 | I24: 8R8RFNS39H9J02079 | J24: BLANCO-ROJO | K24: 2017 | L24: 5 | M24: =IF(H24="","",IF(_xlfn.MAXIFS(Mantenimiento[Fecha Salida],Mantenimiento[Placa Vehiculo],H24)>TODAY(),"Mantenimiento",IF(IFERROR(INDEX(Seguros[Estado Poliza],MATCH(H24,Seguros[Placa Vehiculo],0)),"")="Vencido","Seguro Vencido","Disponible"))) -> Disponible | N24: 250 | P24: 1 | Q24: =_xlfn.MAXIFS(Mantenimiento[Kilometraje del Odómetro],Mantenimiento[Placa Vehiculo],H24,Mantenimiento[Tipo],"Preventivo") -> 2060 | R24: =_xlfn.MAXIFS(Mantenimiento[Kilometraje del Odómetro],Mantenimiento[Placa Vehiculo],H24,Mantenimiento[Tipo],"Prev Caja y Corona") -> 0 | S24: =_xlfn.MAXIFS(Rutas[Kms Final (Odómetro)],Rutas[Placa Vehiculo],H24) -> 2154 | U24: =IF(H24="","",N24-(IF(S24=0,P24,S24)-Q24)) -> 156 | V24: =IFERROR(IF(OR(M24="Mantenimiento",U24/N24<=5%),"Mantener",IF(U24/N24<=20%,"Falta poco","Aun no")),"") -> Aun no
C25: 20 | D25: KR-1090/42407 | E25: VACUMM | F25: VACUUM | G25: 160 BARRILES | H25: KR-1090/42407 | I25: 8R8RFNS2699J01626 | J25: BLANCO-ROJO | K25: 2009 | L25: 5 | M25: =IF(H25="","",IF(_xlfn.MAXIFS(Mantenimiento[Fecha Salida],Mantenimiento[Placa Vehiculo],H25)>TODAY(),"Mantenimiento",IF(IFERROR(INDEX(Seguros[Estado Poliza],MATCH(H25,Seguros[Placa Vehiculo],0)),"")="Vencido","Seguro Vencido","Disponible"))) -> Disponible | N25: 250 | P25: 2000 | Q25: =_xlfn.MAXIFS(Mantenimiento[Kilometraje del Odómetro],Mantenimiento[Placa Vehiculo],H25,Mantenimiento[Tipo],"Preventivo") -> 3007 | R25: =_xlfn.MAXIFS(Mantenimiento[Kilometraje del Odómetro],Mantenimiento[Placa Vehiculo],H25,Mantenimiento[Tipo],"Prev Caja y Corona") -> 0 | S25: =_xlfn.MAXIFS(Rutas[Kms Final (Odómetro)],Rutas[Placa Vehiculo],H25) -> 3000 | U25: =IF(H25="","",N25-(IF(S25=0,P25,S25)-Q25)) -> 257 | V25: =IFERROR(IF(OR(M25="Mantenimiento",U25/N25<=5%),"Mantener",IF(U25/N25<=20%,"Falta poco","Aun no")),"") -> Aun no
C26: 19 | D26: KR-1188/42405 | E26: VACUMM | F26: VACUUM | G26: 160 BARRILES | H26: KR-1188/42405 | I26: 8R8RFNS2299J01851 | J26: BLANCO-ROJO | K26: 2009 | L26: 5 | M26: =IF(H26="","",IF(_xlfn.MAXIFS(Mantenimiento[Fecha Salida],Mantenimiento[Placa Vehiculo],H26)>TODAY(),"Mantenimiento",IF(IFERROR(INDEX(Seguros[Estado Poliza],MATCH(H26,Seguros[Placa Vehiculo],0)),"")="Vencido","Seguro Vencido","Disponible"))) -> Disponible | N26: 250 | P26: 1000 | Q26: =_xlfn.MAXIFS(Mantenimiento[Kilometraje del Odómetro],Mantenimiento[Placa Vehiculo],H26,Mantenimiento[Tipo],"Preventivo") -> 2272 | R26: =_xlfn.MAXIFS(Mantenimiento[Kilometraje del Odómetro],Mantenimiento[Placa Vehiculo],H26,Mantenimiento[Tipo],"Prev Caja y Corona") -> 0 | S26: =_xlfn.MAXIFS(Rutas[Kms Final (Odómetro)],Rutas[Placa Vehiculo],H26) -> 2544 | U26: =IF(H26="","",N26-(IF(S26=0,P26,S26)-Q26)) -> -22 | V26: =IFERROR(IF(OR(M26="Mantenimiento",U26/N26<=5%),"Mantener",IF(U26/N26<=20%,"Falta poco","Aun no")),"") -> Mantener
C27: 21 | D27: KR-1088/42406 | E27: VACUMM | F27: VACUUM | G27: 160 BARRILES | H27: KR-1088/42406 | I27: 8R8RFNS2499J01625 | J27: BLANCO-ROJO | K27: 2009 | L27: 5 | M27: =IF(H27="","",IF(_xlfn.MAXIFS(Mantenimiento[Fecha Salida],Mantenimiento[Placa Vehiculo],H27)>TODAY(),"Mantenimiento",IF(IFERROR(INDEX(Seguros[Estado Poliza],MATCH(H27,Seguros[Placa Vehiculo],0)),"")="Vencido","Seguro Vencido","Disponible"))) -> Disponible | N27: 250 | P27: 1500 | Q27: =_xlfn.MAXIFS(Mantenimiento[Kilometraje del Odómetro],Mantenimiento[Placa Vehiculo],H27,Mantenimiento[Tipo],"Preventivo") -> 3359 | R27: =_xlfn.MAXIFS(Mantenimiento[Kilometraje del Odómetro],Mantenimiento[Placa Vehiculo],H27,Mantenimiento[Tipo],"Prev Caja y Corona") -> 0 | S27: =_xlfn.MAXIFS(Rutas[Kms Final (Odómetro)],Rutas[Placa Vehiculo],H27) -> 3358 | U27: =IF(H27="","",N27-(IF(S27=0,P27,S27)-Q27)) -> 251 | V27: =IFERROR(IF(OR(M27="Mantenimiento",U27/N27<=5%),"Mantener",IF(U27/N27<=20%,"Falta poco","Aun no")),"") -> Aun no
C28: 21 | D28: KR-1185/42408 | E28: VACUMM | F28: VACUUM | G28: 160 BARRILES | H28: KR-1185/42408 | I28: 8R8RFNS2199J01842 | J28: BLANCO-ROJO | K28: 2009 | L28: 5 | M28: =IF(H28="","",IF(_xlfn.MAXIFS(Mantenimiento[Fecha Salida],Mantenimiento[Placa Vehiculo],H28)>TODAY(),"Mantenimiento",IF(IFERROR(INDEX(Seguros[Estado Poliza],MATCH(H28,Seguros[Placa Vehiculo],0)),"")="Vencido","Seguro Vencido","Disponible"))) -> Disponible | N28: 250 | P28: 2000 | Q28: =_xlfn.MAXIFS(Mantenimiento[Kilometraje del Odómetro],Mantenimiento[Placa Vehiculo],H28,Mantenimiento[Tipo],"Preventivo") -> 2438 | R28: =_xlfn.MAXIFS(Mantenimiento[Kilometraje del Odómetro],Mantenimiento[Placa Vehiculo],H28,Mantenimiento[Tipo],"Prev Caja y Corona") -> 0 | S28: =_xlfn.MAXIFS(Rutas[Kms Final (Odómetro)],Rutas[Placa Vehiculo],H28) -> 2695 | U28: =IF(H28="","",N28-(IF(S28=0,P28,S28)-Q28)) -> -7 | V28: =IFERROR(IF(OR(M28="Mantenimiento",U28/N28<=5%),"Mantener",IF(U28/N28<=20%,"Falta poco","Aun no")),"") -> Mantener
C29: 22 | D29: KR-1184/42418 | E29: VACUMM | F29: VACUUM | G29: 160 BARRILES | H29: KR-1184/42418 | I29: 8R8RFNS22B9J01855 | J29: BLANCO-ROJO | K29: 2011 | L29: 5 | M29: =IF(H29="","",IF(_xlfn.MAXIFS(Mantenimiento[Fecha Salida],Mantenimiento[Placa Vehiculo],H29)>TODAY(),"Mantenimiento",IF(IFERROR(INDEX(Seguros[Estado Poliza],MATCH(H29,Seguros[Placa Vehiculo],0)),"")="Vencido","Seguro Vencido","Disponible"))) -> Disponible | N29: 250 | P29: 2 | Q29: =_xlfn.MAXIFS(Mantenimiento[Kilometraje del Odómetro],Mantenimiento[Placa Vehiculo],H29,Mantenimiento[Tipo],"Preventivo") -> 1364 | R29: =_xlfn.MAXIFS(Mantenimiento[Kilometraje del Odómetro],Mantenimiento[Placa Vehiculo],H29,Mantenimiento[Tipo],"Prev Caja y Corona") -> 0 | S29: =_xlfn.MAXIFS(Rutas[Kms Final (Odómetro)],Rutas[Placa Vehiculo],H29) -> 1418 | U29: =IF(H29="","",N29-(IF(S29=0,P29,S29)-Q29)) -> 196 | V29: =IFERROR(IF(OR(M29="Mantenimiento",U29/N29<=5%),"Mantener",IF(U29/N29<=20%,"Falta poco","Aun no")),"") -> Aun no
C30: 23 | D30: KR-1108/42403 | E30: VACUMM | F30: VACUUM | G30: 160 BARRILES | H30: KR-1108/42403 | I30: 8R8RFNS25B9J01624 | J30: BLANCO-ROJO | K30: 2011 | L30: 5 | M30: =IF(H30="","",IF(_xlfn.MAXIFS(Mantenimiento[Fecha Salida],Mantenimiento[Placa Vehiculo],H30)>TODAY(),"Mantenimiento",IF(IFERROR(INDEX(Seguros[Estado Poliza],MATCH(H30,Seguros[Placa Vehiculo],0)),"")="Vencido","Seguro Vencido","Disponible"))) -> Disponible | N30: 250 | P30: 30 | Q30: =_xlfn.MAXIFS(Mantenimiento[Kilometraje del Odómetro],Mantenimiento[Placa Vehiculo],H30,Mantenimiento[Tipo],"Preventivo") -> 4061 | R30: =_xlfn.MAXIFS(Mantenimiento[Kilometraje del Odómetro],Mantenimiento[Placa Vehiculo],H30,Mantenimiento[Tipo],"Prev Caja y Corona") -> 0 | S30: =_xlfn.MAXIFS(Rutas[Kms Final (Odómetro)],Rutas[Placa Vehiculo],H30) -> 4113 | U30: =IF(H30="","",N30-(IF(S30=0,P30,S30)-Q30)) -> 198 | V30: =IFERROR(IF(OR(M30="Mantenimiento",U30/N30<=5%),"Mantener",IF(U30/N30<=20%,"Falta poco","Aun no")),"") -> Aun no
C31: 24 | D31: KR-1094/42424 | E31: VACUMM | F31: VACUUM | G31: 160 BARRILES | H31: KR-1094/42424 | I31: 8R8RFNS22B9J01631 | J31: BLANCO-ROJO | K31: 2011 | L31: 5 | M31: =IF(H31="","",IF(_xlfn.MAXIFS(Mantenimiento[Fecha Salida],Mantenimiento[Placa Vehiculo],H31)>TODAY(),"Mantenimiento",IF(IFERROR(INDEX(Seguros[Estado Poliza],MATCH(H31,Seguros[Placa Vehiculo],0)),"")="Vencido","Seguro Vencido","Disponible"))) -> Disponible | N31: 250 | P31: 30 | Q31: =_xlfn.MAXIFS(Mantenimiento[Kilometraje del Odómetro],Mantenimiento[Placa Vehiculo],H31,Mantenimiento[Tipo],"Preventivo") -> 2258 | R31: =_xlfn.MAXIFS(Mantenimiento[Kilometraje del Odómetro],Mantenimiento[Placa Vehiculo],H31,Mantenimiento[Tipo],"Prev Caja y Corona") -> 0 | S31: =_xlfn.MAXIFS(Rutas[Kms Final (Odómetro)],Rutas[Placa Vehiculo],H31) -> 2266 | U31: =IF(H31="","",N31-(IF(S31=0,P31,S31)-Q31)) -> 242 | V31: =IFERROR(IF(OR(M31="Mantenimiento",U31/N31<=5%),"Mantener",IF(U31/N31<=20%,"Falta poco","Aun no")),"") -> Aun no
C32: 25 | D32: OR-2276 | E32: VACUMM | F32: VACUUM | G32: 200 BARRILES | H32: OR-2276 | I32: 8R8RJMS34S8J01377 | J32: BLANCO-ROJO | K32: 2025 | L32: 5 | M32: =IF(H32="","",IF(_xlfn.MAXIFS(Mantenimiento[Fecha Salida],Mantenimiento[Placa Vehiculo],H32)>TODAY(),"Mantenimiento",IF(IFERROR(INDEX(Seguros[Estado Poliza],MATCH(H32,Seguros[Placa Vehiculo],0)),"")="Vencido","Seguro Vencido","Disponible"))) -> Disponible | N32: 250 | P32: 20 | Q32: =_xlfn.MAXIFS(Mantenimiento[Kilometraje del Odómetro],Mantenimiento[Placa Vehiculo],H32,Mantenimiento[Tipo],"Preventivo") -> 200 | R32: =_xlfn.MAXIFS(Mantenimiento[Kilometraje del Odómetro],Mantenimiento[Placa Vehiculo],H32,Mantenimiento[Tipo],"Prev Caja y Corona") -> 0 | S32: =_xlfn.MAXIFS(Rutas[Kms Final (Odómetro)],Rutas[Placa Vehiculo],H32) -> 366 | U32: =IF(H32="","",N32-(IF(S32=0,P32,S32)-Q32)) -> 84 | V32: =IFERROR(IF(OR(M32="Mantenimiento",U32/N32<=5%),"Mantener",IF(U32/N32<=20%,"Falta poco","Aun no")),"") -> Aun no
C33: 26 | D33: KR1343/42430 | E33: VACUMM | F33: VACUUM | G33: 200 BARRILES | H33: KR-1343/42430 | I33: 8R8RFNS35H9J02080 | J33: BLANCO-ROJO | K33: 2017 | L33: 5 | M33: =IF(H33="","",IF(_xlfn.MAXIFS(Mantenimiento[Fecha Salida],Mantenimiento[Placa Vehiculo],H33)>TODAY(),"Mantenimiento",IF(IFERROR(INDEX(Seguros[Estado Poliza],MATCH(H33,Seguros[Placa Vehiculo],0)),"")="Vencido","Seguro Vencido","Disponible"))) -> Disponible | N33: 250 | P33: 1000 | Q33: =_xlfn.MAXIFS(Mantenimiento[Kilometraje del Odómetro],Mantenimiento[Placa Vehiculo],H33,Mantenimiento[Tipo],"Preventivo") -> 7290 | R33: =_xlfn.MAXIFS(Mantenimiento[Kilometraje del Odómetro],Mantenimiento[Placa Vehiculo],H33,Mantenimiento[Tipo],"Prev Caja y Corona") -> 0 | S33: =_xlfn.MAXIFS(Rutas[Kms Final (Odómetro)],Rutas[Placa Vehiculo],H33) -> 7290 | U33: =IF(H33="","",N33-(IF(S33=0,P33,S33)-Q33)) -> 250 | V33: =IFERROR(IF(OR(M33="Mantenimiento",U33/N33<=5%),"Mantener",IF(U33/N33<=20%,"Falta poco","Aun no")),"") -> Aun no
C34: 27 | D34: OR-2472/42435 | E34: VACUMM | F34: VACUUM | G34: 200 BARRILES | H34: OR-2472/42435 | I34: 8R8RRNS37S8J01601 | J34: BLANCO-ROJO | K34: 2025 | L34: 5 | M34: =IF(H34="","",IF(_xlfn.MAXIFS(Mantenimiento[Fecha Salida],Mantenimiento[Placa Vehiculo],H34)>TODAY(),"Mantenimiento",IF(IFERROR(INDEX(Seguros[Estado Poliza],MATCH(H34,Seguros[Placa Vehiculo],0)),"")="Vencido","Seguro Vencido","Disponible"))) -> Disponible | N34: 250 | P34: 50 | Q34: =_xlfn.MAXIFS(Mantenimiento[Kilometraje del Odómetro],Mantenimiento[Placa Vehiculo],H34,Mantenimiento[Tipo],"Preventivo") -> 704 | R34: =_xlfn.MAXIFS(Mantenimiento[Kilometraje del Odómetro],Mantenimiento[Placa Vehiculo],H34,Mantenimiento[Tipo],"Prev Caja y Corona") -> 0 | S34: =_xlfn.MAXIFS(Rutas[Kms Final (Odómetro)],Rutas[Placa Vehiculo],H34) -> 770 | U34: =IF(H34="","",N34-(IF(S34=0,P34,S34)-Q34)) -> 184 | V34: =IFERROR(IF(OR(M34="Mantenimiento",U34/N34<=5%),"Mantener",IF(U34/N34<=20%,"Falta poco","Aun no")),"") -> Aun no

Sheet Seguros
C1: SEGUROS DE VEHICULOS
C3: Nro | D3: Placa Vehiculo | E3: Aseguradora | F3: Poliza seguro | G3: Fecha de inicio | H3: Fecha de Vencimiento | I3: Importe Pagado ($) | J3: Fecha de Pago | K3: Estado Poliza
C4: =ROW(A1) -> 1 | K4: =IF(H4="","",IF(H4<TODAY(),"Vencido","Vigente"))
C5: =ROW(A2) -> 2 | K5: =IF(H5="","",IF(H5<TODAY(),"Vencido","Vigente"))
C6: =ROW(A3) -> 3 | K6: =IF(H6="","",IF(H6<TODAY(),"Vencido","Vigente"))
C7: =ROW(A4) -> 4 | K7: =IF(H7="","",IF(H7<TODAY(),"Vencido","Vigente"))
C8: =ROW(A5) -> 5 | K8: =IF(H8="","",IF(H8<TODAY(),"Vencido","Vigente"))
C9: =ROW(A6) -> 6 | K9: =IF(H9="","",IF(H9<TODAY(),"Vencido","Vigente"))
C10: =ROW(A7) -> 7 | K10: =IF(H10="","",IF(H10<TODAY(),"Vencido","Vigente"))
C11: =ROW(A8) -> 8 | K11: =IF(H11="","",IF(H11<TODAY(),"Vencido","Vigente"))
C12: =ROW(A9) -> 9 | K12: =IF(H12="","",IF(H12<TODAY(),"Vencido","Vigente"))
C13: =ROW(A10) -> 10 | K13: =IF(H13="","",IF(H13<TODAY(),"Vencido","Vigente"))
C14: =ROW(A11) -> 11 | K14: =IF(H14="","",IF(H14<TODAY(),"Vencido","Vigente"))
C15: =ROW(A12) -> 12 | K15: =IF(H15="","",IF(H15<TODAY(),"Vencido","Vigente"))
... C23: =ROW(A20) -> 20 | K23: =IF(H23="","",IF(H23<TODAY(),"Vencido","Vigente"))

Sheet Impuestos
C1: IMPUESTOS DE VEHICULOS
C3: Nro | D3: Placa Vehiculo | E3: Tipo Impuesto | F3: Año Impuesto | G3: Impuesto ($) | H3: Fecha de pago
C4: =ROW(A1) -> 1
C5: =ROW(A2) -> 2
C6: =ROW(A3) -> 3
C7: =ROW(A4) -> 4
C8: =ROW(A5) -> 5
C9: =ROW(A6) -> 6
C10: =ROW(A7) -> 7
C11: =ROW(A8) -> 8
C12: =ROW(A9) -> 9
C13: =ROW(A10) -> 10
C14: =ROW(A11) -> 11
C15: =ROW(A12) -> 12
... C23: =ROW(A20) -> 20

Sheet Conductores
B1: DATOS DE LOS CONDUCTORES
C3: Nro | D3: Doc Identidad | E3: Conductor | F3: Nro Licencia | G3: Dirección | H3: Teléfono/Celular | I3: Calificación
C4: =ROW(A1) -> 1 | D4: 1716252901 | E4: ARGUELLO PAUCAR JOHN FRANKLIN | F4: 1716252901 | G4: La Joya de los Sachas | I4: ★★★★
C5: =ROW(A2) -> 2 | D5: 0201710944 | E5: BAYAS VASQUEZ PEDRO BENJAMIN | F5: '0201710944 | G5: La Joya de los Sachas | H5: 990941137
C6: =ROW(A3) -> 3 | D6: 2100042452 | E6: BRAVO SONGOR MARCO HERNAN | F6: 2100042452 | G6: La Joya de los Sachas
C7: =ROW(A4) -> 4 | D7: 1723808927 | E7: BRIONES SOLORZANO LEONARDO FABIO | F7: 1723808927 | G7: La Joya de los Sachas
C8: =ROW(A5) -> 5 | D8: 2200112569 | E8: CAMACHO MORENO GILSON ADALBERTO | F8: 2200112569 | G8: La Joya de los Sachas
C9: =ROW(A6) -> 6 | D9: 2200019152 | E9: CAMACHO NARANJO CARLOS ANDRES | F9: 2200019152 | G9: La Joya de los Sachas
C10: =ROW(A7) -> 7 | D10: 2200523484 | E10: CASTILLO VILLALVA EDGAR PATRICIO | F10: 2200523484 | G10: La Joya de los Sachas
C11: =ROW(A8) -> 8 | D11: 2100768163 | E11: CORDOVA CELI ANDRES ALEXANDER | F11: 2100768163 | G11: La Joya de los Sachas
C12: =ROW(A9) -> 9 | D12: 2200300065 | E12: ESTACIO DAVILA EDWIN ALEXIS | F12: 2200300065 | G12: La Joya de los Sachas
C13: =ROW(A10) -> 10 | D13: 1714847884 | E13: GALEAS AGUILA FREDY RODOLFO | F13: 1714847884 | G13: La Joya de los Sachas
C14: =ROW(A11) -> 11 | D14: 1720613981 | E14: LOPEZ GUERRERO CRISTIAN ALEJANDRO | F14: 1720613981 | G14: La Joya de los Sachas
C15: =ROW(A12) -> 12 | D15: 1803398831 | E15: LUNA HERNANDEZ LUIS ALBERTO | F15: 1803398831 | G15: La Joya de los Sachas
C16: =ROW(A13) -> 13 | D16: 2200401434 | E16: MOSCUY RAMIREZ MILVIO PAUL | F16: 2200401434 | G16: La Joya de los Sachas
C17: =ROW(A14) -> 14 | D17: 0802477646 | E17: NAZARENO PALOMINO JORGE MANUEL | F17: 0802477646 | G17: La Joya de los Sachas
C18: =ROW(A15) -> 15 | D18: 1500330251 | E18: ORDOÑEZ CALLE JOSE SALVADOR | F18: 1500330251 | G18: La Joya de los Sachas
C19: =ROW(A16) -> 16 | D19: 2250130446 | E19: ORDOÑEZ MENENDEZ JOSUE ELISEO | F19: 2250130446 | G19: La Joya de los Sachas
C20: =ROW(A17) -> 17 | D20: 1306109628 | E20: PONCE RUIZ SIXTO LUBERNDI | F20: 1306109628 | G20: La Joya de los Sachas
C21: =ROW(A18) -> 18 | D21: 2200002521 | E21: TANDAZO ROSILLO VICTOR HUGO | F21: 2200002521 | G21: La Joya de los Sachas
C22: =ROW(A19) -> 19 | D22: 2200222327 | E22: VARGAS CARAVAJAL ROMEL LEONEL | F22: 2200222327 | G22: La Joya de los Sachas
C23: =ROW(A20) -> 20 | D23: 0504385162 | E23: AGURTO LOPEZ ERWIN JESULIN | F23: 0504385162 | G23: La Joya de los Sachas
C24: =ROW(A21) -> 21 | D24: 1250713219 | E24: ANCHUNDIA LISANDRO | F24: 1250713219 | G24: La Joya de los Sachas
C25: =ROW(A22) -> 22 | D25: 2200383160 | E25: BARRAGAN GARCIA GISSELA NOEMI | F25: 2200383160 | G25: La Joya de los Sachas
C26: =ROW(A23) -> 23 | D26: 2200313860 | E26: CAMACHO ZURITA ALEX ADRIAN | F26: 2200313860 | G26: La Joya de los Sachas
C27: =ROW(A24) -> 24 | D27: 2100274360 | E27: DEL VALLE CASTRO JAIME FERNANDO | F27: 2100274360 | G27: La Joya de los Sachas
C28: =ROW(A25) -> 25 | D28: 2101148886 | E28: GAROFALO PALAGUACHAY YOMAIRA MARICELA | F28: 2101148886 | G28: La Joya de los Sachas
C29: =ROW(A26) -> 26 | D29: 1103796205 | E29: HUANCA MAITA SANTOS ARCECIO | F29: 1103796205 | G29: La Joya de los Sachas
C30: =ROW(A27) -> 27 | D30: 2100573563 | E30: JARAMILLO CONZA LUIS ALBERTO | F30: 2100573563 | G30: La Joya de los Sachas
C31: =ROW(A28) -> 28 | D31: 2200644355 | E31: MANOBANDA SANCHEZ WILMER BENIGNO | F31: 2200644355 | G31: La Joya de los Sachas
C32: =ROW(A29) -> 29 | D32: 2200310676 | E32: MORAN PRIAS PEDRO PABLO | F32: 2200310676 | G32: La Joya de los Sachas
C33: =ROW(A31) -> 31 | D33: 2200247951 | E33: MORENO GALEAS JOSE LEODAN | F33: 2200247951 | G33: La Joya de los Sachas
C34: =ROW(A32) -> 32 | D34: 2100699962 | E34: NARANJO PERALTA VANESSA KATERINE | F34: 2100699962 | G34: La Joya de los Sachas
C35: =ROW(A33) -> 33 | D35: 2100152798 | E35: QUINTANILLA GARCIA LUIS HUMBERTO | F35: 2100152798 | G35: La Joya de los Sachas
C36: =ROW(A34) -> 34 | D36: 2250305303 | E36: QUINTERO BRAVO KAREN LISETH | F36: 2250305303 | G36: La Joya de los Sachas
C37: =ROW(A35) -> 35 | D37: 1105424103 | E37: REYES CELI JAVIER MAURICIO | F37: 1105424103 | G37: La Joya de los Sachas
C38: =ROW(A36) -> 36 | D38: 2100606256 | E38: RIVERA GAONA CARLOS FABIAN | F38: 2100606256 | G38: La Joya de los Sachas
C39: =ROW(A37) -> 37 | E39: TACURI GUEVARA LUIS EDUARDO | G39: La Joya de los Sachas
C40: 38 | E40: SILVA FERNANDO | G40: La Joya de los Sachas
C41: =ROW(A38) -> 38 | E41: SAMANIEGO RICHARD | G41: La Joya de los Sachas
...

Sheet Talleres
B1: TALLERES DE MANTENIMIENTO
C3: Nro | D3: Nombre del Taller | E3: Dirección | F3: Teléfono/Celular | G3: Correo | H3: Contacto Principal
C4: =ROW(A1) -> 1 | D4: MECÁNICA ORIENTOIL | E4: VIA AL COCA KM 3 SECTOR LA PARKER | G4: mecanica-orientoil@hotmail.com | H4: Jefferson Ortiz
C5: =ROW(A2) -> 2 | D5: LUBRICADORA HOMECAR | E5: FRENTE AL SINDICATO DE CHOFERES | F5: 968331684 | G5: jorgerodriguez64@gmail.com | H5: Jorge Rodriguez
C6: =ROW(A3) -> 3 | D6: ORDOÑEZ CAR DETAILING CENTER | E6: AV. FUNDADORES VIA LA PARKER | F6: 995441360 | H6: Juan Carlos Ordoñez
C7: =ROW(A4) -> 4 | D7: LAVADORA Y LUBIRCADORA G & J | E7: SECTOR LOS LAULERES | F7: 993880324 | H7: Govannela Pinargote
C8: =ROW(A5) -> 5
C9: =ROW(A6) -> 6
C10: =ROW(A7) -> 7
C11: =ROW(A8) -> 8
C12: =ROW(A9) -> 9
C13: =ROW(A10) -> 10
C14: =ROW(A11) -> 11
C15: =ROW(A12) -> 12
C16: =ROW(A13) -> 13
C17: =ROW(A14) -> 14
C18: =ROW(A15) -> 15
C19: =ROW(A16) -> 16
... C23: =ROW(A20) -> 20

Sheet Otras listas
B1: OTRAS LISTAS DE DATOS
C3: VEHÍCULO | J3: COMBUSTIBLE | N3: MANTENIMIENTO | U3: OTROS
C5: Tipo Vehiculo | E5: Marcas | G5: Marcas | H5: Modelo | J5: Estación de Combustible | L5: Tipo de Combustible | N5: Tipo Mantenimiento | P5: Paquete de Mantenimiento | R5: Paquete de Mantenimiento | S5: Servicios de Mantenimiento | U5: Infracción | W5: Calificación
C6: ARTICULADO | E6: DAF | G6: DAF | H6: CABEZAL | J6: BASE ORIENTOIL | L6: Diesel | N6: Preventivo | P6: Preventivo 01 | R6: Preventivo 01 | S6: Ajuste del Tiempo del Motor | U6: Accidente imprudencial | W6: ★
C7: CAMIÓN RIGIDO | E7: SHACMAN | G7: SHACMAN | H7: CABEZAL | J7: GASOLINERA MIRAFLORES | L7: GLP | N7: Correctivo | P7: Preventivo 02 | R7: Preventivo 01 | S7: Cambio de Aceite y Filtro de Aceite | U7: Alta velocidad | W7: ★★
C8: VACUMM | E8: HINO | G8: HINO | H8: RIGIDO | J8: GASOLINERA SAN JOSE | L8: GASOLINA | N8: Prev Caja y Corona | P8: Preventivo 03 | R8: Preventivo 01 | S8: Cambio de Filtro de Aire | U8: Conductor alcoholizado | W8: ★★★
C9: CAMIONETA | E9: VACUUM | G9: HINO | H9: CABEZAL | J9: ESTACIÓN PARAÍSO | L9: Premium | P9: Preventivo 04 | R9: Preventivo 01 | S9: Inspección de la Correa de Distribución | U9: Conductor temerario | W9: ★★★★
E10: CHEVROLET | G10: VACUUM | H10: 130 BARRILES | J10: CABEZAL | P10: Preventivo 05 | R10: Preventivo 01 | S10: Inspección del Sistema de Frenos | U10: Mal estacionado | W10: ★★★★★
E11: QINGLING | G11: VACUUM | H11: 160 BARRILES | J11: GASOLINERA DIVINO NIÑO | P11: Correctivo 01 | R11: Preventivo 02 | S11: Inspección del Sistema de Suspensión | U11: Se pasó la luz roja
G12: VACUUM | H12: 200 BARRILES | J12: GASOLINERA P&S | P12: Correctivo 02 | R12: Preventivo 02 | S12: Mantenimiento de la Batería
G13: CHEVROLET | H13: DMAX | P13: Correctivo 03 | R13: Preventivo 02 | S13: Mantenimiento del Sistema de Combustible
G14: QINGLING | H14: CABEZAL | P14: Correctivo 04 | R14: Preventivo 02 | S14: Mantenimiento del Sistema de Dirección
P15: Correctivo 05 | R15: Preventivo 03 | S15: Reemplazo de Bujías, Cables y Correas Serpentinas
P16: Correctivo 06 | R16: Preventivo 03 | S16: Revisión de Amortiguadores
P17: Correctivo 07 | R17: Preventivo 03 | S17: Revisión de Luces
P18: Correctivo 08 | R18: Preventivo 03 | S18: Revisión del Dispositivo de Acoplamiento
P19: Correctivo 09 | R19: Preventivo 04 | S19: Revisión del Sistema de Admisión, Mangueras y Tuberías
P20: Correctivo 10 | R20: Preventivo 04 | S20: Revisión del Sistema de Escape
P21: Caja y Corona 01 | R21: Preventivo 04 | S21: Servicio Completo de Mantenimiento Automotriz
P22: Caja y Corona 02 | R22: Preventivo 05 | S22: Verificación de Neumáticos
P23: Caja y Corona 03 | R23: Preventivo 05 | S23: Verificación de Niveles de Fluidos
P24: Caja y Corona 04 | R24: Preventivo 05 | S24: Verificación del Funcionamiento del Motor
P25: Caja Y Corona 05 | R25: Preventivo 05 | S25: Verificación del Sistema de Transmisión
R26: Correctivo 01 | S26: Planchado y pintado
R27: Correctivo 02 | S27: Cambio de puertas
R28: Correctivo 03 | S28: Eliminación de inperfecciones de la pintura

Sheet Rutas
B1: RUTAS DE VIAJE
C3: Nro | D3: Fecha de Salida | E3: Fecha de Llegada | F3: Placa Vehiculo | G3: Estado Vehículo | H3: Conductor | I3: Origen | J3: Destino | K3: Kms Inicial (Odómetro) | L3: Kms Final (Odómetro) | M3: Kms Recorridos | N3: Horas trabjadas | O3: Peso de carga (BLS) | P3: Costo por Km de carga ($/Km) | Q3: Ingreso Total ($) | R3: Estación de Combustible | S3: Tipo de Combustible | T3: Precio x Galón ($/gal) | U3: Total Combustible ($) | V3: Gasto peajes ($) | W3: Gasto comidas ($) | X3: Otros Gastos ($) | Y3: Gasto Total ($) | Z3: TICKET | AA3: Volumen de Combustible (gal) | AB3: Recorrido por und. de comb. (Km/gal) | AC3: Ingreso por Kms de recorrido ($/Km) | AD3: Observaciones
C4: =ROW(A1) -> 1 | D4: 45630 | E4: 45633 | F4: QAA-2912 | G4: =IF(AND(E4<>"",E4<TODAY()),"Disponible",IFERROR(INDEX(Vehiculos[Estado Vehiculo],MATCH(F4,Vehiculos[Placa Vehiculo],0)),"")) -> Disponible | H4: MOSCUY RAMIREZ MILVIO PAUL | I4: BASE ORIENTOIL | J4: MDC | K4: 67507 | L4: 68206 | M4: =L4-K4 -> 699 | P4: 5 | Q4: =M4*P4 -> 3495 | R4: BASE ORIENTOIL | S4: Diesel | T4: 1.8 | U4: =Rutas[[#This Row],[Precio x Galón ($/gal)]]*Rutas[[#This Row],[Volumen de Combustible (gal)]] -> 192.834 | Y4: =U4+SUM(V4:X4) -> 192.834 | AA4: 107.13 | AB4: =IFERROR(M4/AA4,0) -> 6.524783 | AC4: =IFERROR(Q4/M4,0) -> 5
C5: =ROW(A2) -> 2 | D5: 45633 | E5: 45639 | F5: QAA-2912 | G5: =IF(AND(E5<>"",E5<TODAY()),"Disponible",IFERROR(INDEX(Vehiculos[Estado Vehiculo],MATCH(F5,Vehiculos[Placa Vehiculo],0)),"")) -> Disponible | H5: MOSCUY RAMIREZ MILVIO PAUL | I5: BASE ORIENTOIL | J5: MDC | K5: 68206 | L5: 68985 | M5: =L5-K5 -> 779 | Q5: =M5*P5 -> 0 | R5: BASE ORIENTOIL | S5: Diesel | T5: 1.8 | U5: =Rutas[[#This Row],[Precio x Galón ($/gal)]]*Rutas[[#This Row],[Volumen de Combustible (gal)]] -> 184.32 | Y5: =U5+SUM(V5:X5) -> 184.32 | AA5: 102.4 | AB5: =IFERROR(M5/AA5,0) -> 7.6074219 | AC5: =IFERROR(Q5/M5,0) -> 0
C6: =ROW(A3) -> 3 | D6: 45639 | E6: 45645 | F6: QAA-2912 | G6: =IF(AND(E6<>"",E6<TODAY()),"Disponible",IFERROR(INDEX(Vehiculos[Estado Vehiculo],MATCH(F6,Vehiculos[Placa Vehiculo],0)),"")) -> Disponible | H6: MOSCUY RAMIREZ MILVIO PAUL | I6: BASE ORIENTOIL | J6: MDC | K6: 68985 | L6: 69722 | M6: =L6-K6 -> 737 | Q6: =M6*P6 -> 0 | R6: BASE ORIENTOIL | S6: Diesel | T6: 1.8 | U6: =Rutas[[#This Row],[Precio x Galón ($/gal)]]*Rutas[[#This Row],[Volumen de Combustible (gal)]] -> 186.498 | Y6: =U6+SUM(V6:X6) -> 186.498 | AA6: 103.61 | AB6: =IFERROR(M6/AA6,0) -> 7.113213 | AC6: =IFERROR(Q6/M6,0) -> 0
C7: =ROW(A4) -> 4 | D7: 45645 | E7: 45650 | F7: QAA-2912 | G7: =IF(AND(E7<>"",E7<TODAY()),"Disponible",IFERROR(INDEX(Vehiculos[Estado Vehiculo],MATCH(F7,Vehiculos[Placa Vehiculo],0)),"")) -> Disponible | H7: MOSCUY RAMIREZ MILVIO PAUL | I7: BASE ORIENTOIL | J7: MDC | K7: 69722 | L7: 70409 | M7: =L7-K7 -> 687 | Q7: =M7*P7 -> 0 | R7: BASE ORIENTOIL | S7: Diesel | T7: 1.8 | U7: =Rutas[[#This Row],[Precio x Galón ($/gal)]]*Rutas[[#This Row],[Volumen de Combustible (gal)]] -> 177.318 | Y7: =U7+SUM(V7:X7) -> 177.318 | AA7: 98.51 | AB7: =IFERROR(M7/AA7,0) -> 6.9739113 | AC7: =IFERROR(Q7/M7,0) -> 0
C8: =ROW(A5) -> 5 | D8: 45650 | E8: 45656 | F8: QAA-2912 | G8: =IF(AND(E8<>"",E8<TODAY()),"Disponible",IFERROR(INDEX(Vehiculos[Estado Vehiculo],MATCH(F8,Vehiculos[Placa Vehiculo],0)),"")) -> Disponible | H8: MOSCUY RAMIREZ MILVIO PAUL | I8: BASE ORIENTOIL | J8: MDC | K8: 70409 | L8: 71246 | M8: =L8-K8 -> 837 | Q8: =M8*P8 -> 0 | R8: BASE ORIENTOIL | S8: Diesel | T8: 1.8 | U8: =Rutas[[#This Row],[Precio x Galón ($/gal)]]*Rutas[[#This Row],[Volumen de Combustible (gal)]] -> 177.822 | Y8: =U8+SUM(V8:X8) -> 177.822 | AA8: 98.79 | AB8: =IFERROR(M8/AA8,0) -> 8.4725175 | AC8: =IFERROR(Q8/M8,0) -> 0
C9: =ROW(A6) -> 6 | D9: 45656 | E9: 45657 | F9: QAA-2912 | G9: =IF(AND(E9<>"",E9<TODAY()),"Disponible",IFERROR(INDEX(Vehiculos[Estado Vehiculo],MATCH(F9,Vehiculos[Placa Vehiculo],0)),"")) -> Disponible | H9: MOSCUY RAMIREZ MILVIO PAUL | I9: BASE ORIENTOIL | J9: MDC | K9: 71246 | L9: 71946 | M9: =L9-K9 -> 700 | Q9: =M9*P9 -> 0 | R9: BASE ORIENTOIL | S9: Diesel | T9: 1.8 | U9: =Rutas[[#This Row],[Precio x Galón ($/gal)]]*Rutas[[#This Row],[Volumen de Combustible (gal)]] -> 203.328 | Y9: =U9+SUM(V9:X9) -> 203.328 | AA9: 112.96 | AB9: =IFERROR(M9/AA9,0) -> 6.1968839 | AC9: =IFERROR(Q9/M9,0) -> 0
C10: =ROW(A7) -> 7 | D10: 45628 | E10: 45635 | F10: QAA-2916 | G10: =IF(AND(E10<>"",E10<TODAY()),"Disponible",IFERROR(INDEX(Vehiculos[Estado Vehiculo],MATCH(F10,Vehiculos[Placa Vehiculo],0)),"")) -> Disponible | H10: PONCE RUIZ SIXTO LUBERNDI | I10: BASE ORIENTOIL | J10: MDC | K10: 53731 | L10: 54435 | M10: =L10-K10 -> 704 | Q10: =M10*P10 -> 0 | R10: BASE ORIENTOIL | S10: Diesel | T10: 1.8 | U10: =Rutas[[#This Row],[Precio x Galón ($/gal)]]*Rutas[[#This Row],[Volumen de Combustible (gal)]] -> 154.26 | Y10: =U10+SUM(V10:X10) -> 154.26 | AA10: 85.7 | AB10: =IFERROR(M10/AA10,0) -> 8.2147025 | AC10: =IFERROR(Q10/M10,0) -> 0
C11: =ROW(A8) -> 8 | D11: 45635 | E11: 45641 | F11: QAA-2916 | G11: =IF(AND(E11<>"",E11<TODAY()),"Disponible",IFERROR(INDEX(Vehiculos[Estado Vehiculo],MATCH(F11,Vehiculos[Placa Vehiculo],0)),"")) -> Disponible | H11: PONCE RUIZ SIXTO LUBERNDI | I11: BASE ORIENTOIL | J11: MDC | K11: 54435 | L11: 55268 | M11: =L11-K11 -> 833 | Q11: =M11*P11 -> 0 | R11: BASE ORIENTOIL | S11: Diesel | T11: 1.8 | U11: =Rutas[[#This Row],[Precio x Galón ($/gal)]]*Rutas[[#This Row],[Volumen de Combustible (gal)]] -> 197.748 | Y11: =U11+SUM(V11:X11) -> 197.748 | AA11: 109.86 | AB11: =IFERROR(M11/AA11,0) -> 7.5823776 | AC11: =IFERROR(Q11/M11,0) -> 0
C12: =ROW(A9) -> 9 | D12: 45641 | E12: 45647 | F12: QAA-2916 | G12: =IF(AND(E12<>"",E12<TODAY()),"Disponible",IFERROR(INDEX(Vehiculos[Estado Vehiculo],MATCH(F12,Vehiculos[Placa Vehiculo],0)),"")) -> Disponible | H12: BRIONES SOLORZANO LEONARDO FABIO | I12: BASE ORIENTOIL | J12: MDC | K12: 55268 | L12: 55943 | M12: =L12-K12 -> 675 | Q12: =M12*P12 -> 0 | R12: BASE ORIENTOIL | S12: Diesel | T12: 1.8 | U12: =Rutas[[#This Row],[Precio x Galón ($/gal)]]*Rutas[[#This Row],[Volumen de Combustible (gal)]] -> 211.482 | Y12: =U12+SUM(V12:X12) -> 211.482 | AA12: 117.49 | AB12: =IFERROR(M12/AA12,0) -> 5.7451698 | AC12: =IFERROR(Q12/M12,0) -> 0
C13: =ROW(A10) -> 10 | D13: 45647 | E13: 45652 | F13: QAA-2916 | G13: =IF(AND(E13<>"",E13<TODAY()),"Disponible",IFERROR(INDEX(Vehiculos[Estado Vehiculo],MATCH(F13,Vehiculos[Placa Vehiculo],0)),"")) -> Disponible | H13: BRIONES SOLORZANO LEONARDO FABIO | I13: BASE ORIENTOIL | J13: MDC | K13: 55943 | L13: 56624 | M13: =L13-K13 -> 681 | Q13: =M13*P13 -> 0 | R13: BASE ORIENTOIL | S13: Diesel | T13: 1.8 | U13: =Rutas[[#This Row],[Precio x Galón ($/gal)]]*Rutas[[#This Row],[Volumen de Combustible (gal)]] -> 293.706 | Y13: =U13+SUM(V13:X13) -> 293.706 | AA13: 163.17 | AB13: =IFERROR(M13/AA13,0) -> 4.1735613 | AC13: =IFERROR(Q13/M13,0) -> 0
C14: =ROW(A11) -> 11 | D14: 45652 | E14: 45656 | F14: QAA-2916 | G14: =IF(AND(E14<>"",E14<TODAY()),"Disponible",IFERROR(INDEX(Vehiculos[Estado Vehiculo],MATCH(F14,Vehiculos[Placa Vehiculo],0)),"")) -> Disponible | H14: PONCE RUIZ SIXTO LUBERNDI | I14: BASE ORIENTOIL | J14: MDC | K14: 56624 | L14: 57355 | M14: =L14-K14 -> 731 | Q14: =M14*P14 -> 0 | R14: BASE ORIENTOIL | S14: Diesel | T14: 1.8 | U14: =Rutas[[#This Row],[Precio x Galón ($/gal)]]*Rutas[[#This Row],[Volumen de Combustible (gal)]] -> 176.22 | Y14: =U14+SUM(V14:X14) -> 176.22 | AA14: 97.9 | AB14: =IFERROR(M14/AA14,0) -> 7.4668029 | AC14: =IFERROR(Q14/M14,0) -> 0
C15: =ROW(A12) -> 12 | D15: 45627 | E15: 45631 | F15: QAA-2915 | G15: =IF(AND(E15<>"",E15<TODAY()),"Disponible",IFERROR(INDEX(Vehiculos[Estado Vehiculo],MATCH(F15,Vehiculos[Placa Vehiculo],0)),"")) -> Disponible | H15: NAZARENO PALOMINO JORGE MANUEL | I15: BASE ORIENTOIL | J15: MDC | K15: 62880 | L15: 63639 | M15: =L15-K15 -> 759 | Q15: =M15*P15 -> 0 | R15: BASE ORIENTOIL | S15: Diesel | T15: 1.8 | U15: =Rutas[[#This Row],[Precio x Galón ($/gal)]]*Rutas[[#This Row],[Volumen de Combustible (gal)]] -> 223.848 | Y15: =U15+SUM(V15:X15) -> 223.848 | AA15: 124.36 | AB15: =IFERROR(M15/AA15,0) -> 6.1032486 | AC15: =IFERROR(Q15/M15,0) -> 0
C16: =ROW(A13) -> 13 | D16: 45631 | E16: 45634 | F16: QAA-2915 | G16: =IF(AND(E16<>"",E16<TODAY()),"Disponible",IFERROR(INDEX(Vehiculos[Estado Vehiculo],MATCH(F16,Vehiculos[Placa Vehiculo],0)),"")) -> Disponible | H16: LUNA HERNANDEZ LUIS ALBERTO | I16: BASE ORIENTOIL | J16: MDC | K16: 63639 | L16: 64228 | M16: =L16-K16 -> 589 | Q16: =M16*P16 -> 0 | R16: BASE ORIENTOIL | S16: Diesel | T16: 1.8 | U16: =Rutas[[#This Row],[Precio x Galón ($/gal)]]*Rutas[[#This Row],[Volumen de Combustible (gal)]] -> 218.214 | Y16: =U16+SUM(V16:X16) -> 218.214 | AA16: 121.23 | AB16: =IFERROR(M16/AA16,0) -> 4.8585334 | AC16: =IFERROR(Q16/M16,0) -> 0
... C47: =ROW(A44) -> 44 | D47: 45635 | E47: 45638 | F47: QAA-3166 | G47: =IF(AND(E47<>"",E47<TODAY()),"Disponible",IFERROR(INDEX(Vehiculos[Estado Vehiculo],MATCH(F47,Vehiculos[Placa Vehiculo],0)),"")) -> Disponible | H47: ORDOÑEZ CALLE JOSE SALVADOR | I47: BASE ORIENTOIL | J47: INCHI | K47: 22372 | L47: 23343 | M47: =L47-K47 -> 971 | Q47: =M47*P47 -> 0 | R47: BASE ORIENTOIL | S47: Diesel | T47: 1.8 | U47: =Rutas[[#This Row],[Precio x Galón ($/gal)]]*Rutas[[#This Row],[Volumen de Combustible (gal)]] -> 214.434 | Y47: =U47+SUM(V47:X47) -> 214.434 | AA47: 119.13 | AB47: =IFERROR(M47/AA47,0) -> 8.1507597 | AC47: =IFERROR(Q47/M47,0) -> 0
C48: =ROW(A45) -> 45 | D48: 45638 | E48: 45642 | F48: QAA-3166 | G48: =IF(AND(E48<>"",E48<TODAY()),"Disponible",IFERROR(INDEX(Vehiculos[Estado Vehiculo],MATCH(F48,Vehiculos[Placa Vehiculo],0)),"")) -> Disponible | H48: ORDOÑEZ CALLE JOSE SALVADOR | I48: BASE ORIENTOIL | J48: INCHI | K48: =L47 -> 23343 | L48: 24491 | M48: =L48-K48 -> 1148 | Q48: =M48*P48 -> 0 | R48: BASE ORIENTOIL | S48: Diesel | T48: 1.8 | U48: =Rutas[[#This Row],[Precio x Galón ($/gal)]]*Rutas[[#This Row],[Volumen de Combustible (gal)]] -> 268.2 | Y48: =U48+SUM(V48:X48) -> 268.2 | AA48: 149 | AB48: =IFERROR(M48/AA48,0) -> 7.704698 | AC48: =IFERROR(Q48/M48,0) -> 0
C49: =ROW(A46) -> 46 | D49: 45642 | E49: 45645 | F49: QAA-3166 | G49: =IF(AND(E49<>"",E49<TODAY()),"Disponible",IFERROR(INDEX(Vehiculos[Estado Vehiculo],MATCH(F49,Vehiculos[Placa Vehiculo],0)),"")) -> Disponible | H49: GALEAS AGUILA FREDY RODOLFO | I49: BASE ORIENTOIL | J49: INCHI | K49: =L48 -> 24491 | L49: 25568 | M49: =L49-K49 -> 1077 | Q49: =M49*P49 -> 0 | R49: BASE ORIENTOIL | S49: Diesel | T49: 1.8 | U49: =Rutas[[#This Row],[Precio x Galón ($/gal)]]*Rutas[[#This Row],[Volumen de Combustible (gal)]] -> 287.298 | Y49: =U49+SUM(V49:X49) -> 287.298 | AA49: 159.61 | AB49: =IFERROR(M49/AA49,0) -> 6.7476975 | AC49: =IFERROR(Q49/M49,0) -> 0
C50: =ROW(A47) -> 47 | D50: 45645 | E50: 45647 | F50: QAA-3166 | G50: =IF(AND(E50<>"",E50<TODAY()),"Disponible",IFERROR(INDEX(Vehiculos[Estado Vehiculo],MATCH(F50,Vehiculos[Placa Vehiculo],0)),"")) -> Disponible | H50: GALEAS AGUILA FREDY RODOLFO | I50: BASE ORIENTOIL | J50: INCHI | K50: =L49 -> 25568 | L50: 26327 | M50: =L50-K50 -> 759 | Q50: =M50*P50 -> 0 | R50: BASE ORIENTOIL | S50: Diesel | T50: 1.8 | U50: =Rutas[[#This Row],[Precio x Galón ($/gal)]]*Rutas[[#This Row],[Volumen de Combustible (gal)]] -> 267.84 | Y50: =U50+SUM(V50:X50) -> 267.84 | AA50: 148.8 | AB50: =IFERROR(M50/AA50,0) -> 5.1008065 | AC50: =IFERROR(Q50/M50,0) -> 0
C51: =ROW(A48) -> 48 | D51: 45647 | E51: 45649 | F51: QAA-3166 | G51: =IF(AND(E51<>"",E51<TODAY()),"Disponible",IFERROR(INDEX(Vehiculos[Estado Vehiculo],MATCH(F51,Vehiculos[Placa Vehiculo],0)),"")) -> Disponible | H51: GALEAS AGUILA FREDY RODOLFO | I51: BASE ORIENTOIL | J51: INCHI | K51: =L50 -> 26327 | L51: 27000 | M51: =L51-K51 -> 673 | Q51: =M51*P51 -> 0 | R51: BASE ORIENTOIL | S51: Diesel | T51: 1.8 | U51: =Rutas[[#This Row],[Precio x Galón ($/gal)]]*Rutas[[#This Row],[Volumen de Combustible (gal)]] -> 195.93 | Y51: =U51+SUM(V51:X51) -> 195.93 | AA51: 108.85 | AB51: =IFERROR(M51/AA51,0) -> 6.1828204 | AC51: =IFERROR(Q51/M51,0) -> 0
C52: =ROW(A49) -> 49 | D52: 45649 | E52: 45652 | F52: QAA-3166 | G52: =IF(AND(E52<>"",E52<TODAY()),"Disponible",IFERROR(INDEX(Vehiculos[Estado Vehiculo],MATCH(F52,Vehiculos[Placa Vehiculo],0)),"")) -> Disponible | H52: CORDOVA CELI ANDRES ALEXANDER | I52: BASE ORIENTOIL | J52: INCHI | K52: =L51 -> 27000 | L52: 27922 | M52: =L52-K52 -> 922 | Q52: =M52*P52 -> 0 | R52: BASE ORIENTOIL | S52: Diesel | T52: 1.8 | U52: =Rutas[[#This Row],[Precio x Galón ($/gal)]]*Rutas[[#This Row],[Volumen de Combustible (gal)]] -> 180.018 | Y52: =U52+SUM(V52:X52) -> 180.018 | AA52: 100.01 | AB52: =IFERROR(M52/AA52,0) -> 9.2190781 | AC52: =IFERROR(Q52/M52,0) -> 0
C53: =ROW(A50) -> 50 | D53: 45652 | E53: 45654 | F53: QAA-3166 | G53: =IF(AND(E53<>"",E53<TODAY()),"Disponible",IFERROR(INDEX(Vehiculos[Estado Vehiculo],MATCH(F53,Vehiculos[Placa Vehiculo],0)),"")) -> Disponible | H53: CORDOVA CELI ANDRES ALEXANDER | I53: BASE ORIENTOIL | J53: INCHI | K53: =L52 -> 27922 | L53: 28837 | M53: =L53-K53 -> 915 | Q53: =M53*P53 -> 0 | R53: BASE ORIENTOIL | S53: Diesel | T53: 1.8 | U53: =Rutas[[#This Row],[Precio x Galón ($/gal)]]*Rutas[[#This Row],[Volumen de Combustible (gal)]] -> 260.298 | Y53: =U53+SUM(V53:X53) -> 260.298 | AA53: 144.61 | AB53: =IFERROR(M53/AA53,0) -> 6.3273633 | AC53: =IFERROR(Q53/M53,0) -> 0
C54: =ROW(A51) -> 51 | D54: 45654 | E54: 45657 | F54: QAA-3166 | G54: =IF(AND(E54<>"",E54<TODAY()),"Disponible",IFERROR(INDEX(Vehiculos[Estado Vehiculo],MATCH(F54,Vehiculos[Placa Vehiculo],0)),"")) -> Disponible | H54: CORDOVA CELI ANDRES ALEXANDER | I54: BASE ORIENTOIL | J54: INCHI | K54: =L53 -> 28837 | L54: 29721 | M54: =L54-K54 -> 884 | Q54: =M54*P54 -> 0 | R54: BASE ORIENTOIL | S54: Diesel | T54: 1.8 | U54: =Rutas[[#This Row],[Precio x Galón ($/gal)]]*Rutas[[#This Row],[Volumen de Combustible (gal)]] -> 224.874 | Y54: =U54+SUM(V54:X54) -> 224.874 | AA54: 124.93 | AB54: =IFERROR(M54/AA54,0) -> 7.0759625 | AC54: =IFERROR(Q54/M54,0) -> 0
C55: =ROW(A52) -> 52 | D55: 45657 | E55: 45657 | F55: QAA-3166 | G55: =IF(AND(E55<>"",E55<TODAY()),"Disponible",IFERROR(INDEX(Vehiculos[Estado Vehiculo],MATCH(F55,Vehiculos[Placa Vehiculo],0)),"")) -> Disponible | H55: CORDOVA CELI ANDRES ALEXANDER | I55: BASE ORIENTOIL | J55: INCHI | K55: =L54 -> 29721 | L55: 30443 | M55: =L55-K55 -> 722 | Q55: =M55*P55 -> 0 | R55: BASE ORIENTOIL | S55: Diesel | T55: 1.8 | U55: =Rutas[[#This Row],[Precio x Galón ($/gal)]]*Rutas[[#This Row],[Volumen de Combustible (gal)]] -> 184.59 | Y55: =U55+SUM(V55:X55) -> 184.59 | AA55: 102.55 | AB55: =IFERROR(M55/AA55,0) -> 7.0404681 | AC55: =IFERROR(Q55/M55,0) -> 0
C56: =ROW(A53) -> 53 | D56: 45509 | E56: 45634 | F56: PFF-2857 | G56: =IF(AND(E56<>"",E56<TODAY()),"Disponible",IFERROR(INDEX(Vehiculos[Estado Vehiculo],MATCH(F56,Vehiculos[Placa Vehiculo],0)),"")) -> Disponible | H56: TACURI GUEVARA LUIS EDUARDO | I56: BASE ORIENTOIL | J56: SUPERVISOR | K56: 68869 | L56: 69453 | M56: =L56-K56 -> 584 | Q56: =M56*P56 -> 0 | R56: BASE ORIENTOIL | S56: Diesel | T56: 1.8 | U56: =Rutas[[#This Row],[Precio x Galón ($/gal)]]*Rutas[[#This Row],[Volumen de Combustible (gal)]] -> 27.45 | Y56: =U56+SUM(V56:X56) -> 27.45 | AA56: 15.25 | AB56: =IFERROR(M56/AA56,0) -> 38.295082 | AC56: =IFERROR(Q56/M56,0) -> 0
C57: =ROW(A54) -> 54 | D57: =E56 -> 45634 | E57: 45637 | F57: PFF-2857 | G57: =IF(AND(E57<>"",E57<TODAY()),"Disponible",IFERROR(INDEX(Vehiculos[Estado Vehiculo],MATCH(F57,Vehiculos[Placa Vehiculo],0)),"")) -> Disponible | H57: TACURI GUEVARA LUIS EDUARDO | I57: BASE ORIENTOIL | J57: SUPERVISOR | K57: =L56 -> 69453 | L57: 70164 | M57: =L57-K57 -> 711 | Q57: =M57*P57 -> 0 | R57: BASE ORIENTOIL | S57: Diesel | T57: 1.8 | U57: =Rutas[[#This Row],[Precio x Galón ($/gal)]]*Rutas[[#This Row],[Volumen de Combustible (gal)]] -> 25.002 | Y57: =U57+SUM(V57:X57) -> 25.002 | AA57: 13.89 | AB57: =IFERROR(M57/AA57,0) -> 51.187905 | AC57: =IFERROR(Q57/M57,0) -> 0
C58: =ROW(A55) -> 55 | D58: =E57 -> 45637 | E58: 45640 | F58: PFF-2857 | G58: =IF(AND(E58<>"",E58<TODAY()),"Disponible",IFERROR(INDEX(Vehiculos[Estado Vehiculo],MATCH(F58,Vehiculos[Placa Vehiculo],0)),"")) -> Disponible | H58: TACURI GUEVARA LUIS EDUARDO | I58: BASE ORIENTOIL | J58: SUPERVISOR | K58: =L57 -> 70164 | L58: 70755 | M58: =L58-K58 -> 591 | Q58: =M58*P58 -> 0 | R58: BASE ORIENTOIL | S58: Diesel | T58: 1.8 | U58: =Rutas[[#This Row],[Precio x Galón ($/gal)]]*Rutas[[#This Row],[Volumen de Combustible (gal)]] -> 28.944 | Y58: =U58+SUM(V58:X58) -> 28.944 | AA58: 16.08 | AB58: =IFERROR(M58/AA58,0) -> 36.753731 | AC58: =IFERROR(Q58/M58,0) -> 0
C59: =ROW(A56) -> 56 | D59: =E58 -> 45640 | E59: 45647 | F59: PFF-2857 | G59: =IF(AND(E59<>"",E59<TODAY()),"Disponible",IFERROR(INDEX(Vehiculos[Estado Vehiculo],MATCH(F59,Vehiculos[Placa Vehiculo],0)),"")) -> Disponible | H59: TACURI GUEVARA LUIS EDUARDO | I59: BASE ORIENTOIL | J59: SUPERVISOR | K59: =L58 -> 70755 | L59: 72398 | M59: =L59-K59 -> 1643 | Q59: =M59*P59 -> 0 | R59: BASE ORIENTOIL | S59: Diesel | T59: 1.8 | U59: =Rutas[[#This Row],[Precio x Galón ($/gal)]]*Rutas[[#This Row],[Volumen de Combustible (gal)]] -> 26.082 | Y59: =U59+SUM(V59:X59) -> 26.082 | AA59: 14.49 | AB59: =IFERROR(M59/AA59,0) -> 113.38854 | AC59: =IFERROR(Q59/M59,0) -> 0
C60: =ROW(A57) -> 57 | D60: =E59 -> 45647 | E60: 45653 | F60: PFF-2857 | G60: =IF(AND(E60<>"",E60<TODAY()),"Disponible",IFERROR(INDEX(Vehiculos[Estado Vehiculo],MATCH(F60,Vehiculos[Placa Vehiculo],0)),"")) -> Disponible | H60: SILVA FERNANDO | I60: BASE ORIENTOIL | J60: SUPERVISOR | K60: =L59 -> 72398 | L60: 73069 | M60: =L60-K60 -> 671 | Q60: =M60*P60 -> 0 | R60: BASE ORIENTOIL | S60: Diesel | T60: 1.8 | U60: =Rutas[[#This Row],[Precio x Galón ($/gal)]]*Rutas[[#This Row],[Volumen de Combustible (gal)]] -> 28.35 | Y60: =U60+SUM(V60:X60) -> 28.35 | AA60: 15.75 | AB60: =IFERROR(M60/AA60,0) -> 42.603175 | AC60: =IFERROR(Q60/M60,0) -> 0
C61: =ROW(A58) -> 58 | D61: =E60 -> 45653 | E61: 45654 | F61: PFF-2857 | G61: =IF(AND(E61<>"",E61<TODAY()),"Disponible",IFERROR(INDEX(Vehiculos[Estado Vehiculo],MATCH(F61,Vehiculos[Placa Vehiculo],0)),"")) -> Disponible | H61: SILVA FERNANDO | I61: BASE ORIENTOIL | J61: SUPERVISOR | K61: =L60 -> 73069 | L61: 73385 | M61: =L61-K61 -> 316 | Q61: =M61*P61 -> 0 | R61: BASE ORIENTOIL | S61: Diesel | T61: 1.8 | U61: =Rutas[[#This Row],[Precio x Galón ($/gal)]]*Rutas[[#This Row],[Volumen de Combustible (gal)]] -> 18.9 | Y61: =U61+SUM(V61:X61) -> 18.9 | AA61: 10.5 | AB61: =IFERROR(M61/AA61,0) -> 30.095238 | AC61: =IFERROR(Q61/M61,0) -> 0
